Workbook

Sheet PIVOT TABLE
B1: Total and average impressions, likes, and clicks per campaign
A4: Row Labels | B4: Sum of Impressions | C4: Average of Impressions | D4: Sum of Clicks | E4: Average of Clicks | F4: Sum of Likes | G4: Average of Likes
A5: (blank) | B5: 1830608 | C5: 32689.429 | D5: 8339 | E5: 148.91071 | F5: 150160 | G5: 2681.4286
A6: DailyWellness | B6: 2464864 | C6: 34716.394 | D6: 10689 | E6: 150.5493 | F6: 187909 | G6: 2646.6056
A7: FestiveRadiance | B7: 1986356 | C7: 34247.517 | D7: 9872 | E7: 170.2069 | F7: 159783 | G7: 2754.8793
A8: NewYearRefresh | B8: 2266053 | C8: 33821.687 | D8: 10032 | E8: 149.73134 | F8: 183346 | G8: 2736.5075
A9: SummerSplash | B9: 1846272 | C9: 38464 | D9: 6434 | E9: 134.04167 | F9: 138793 | G9: 2891.5208
A10: Grand Total | B10: 10394153 | C10: 34647.177 | D10: 45366 | E10: 151.22 | F10: 819991 | G10: 2733.3033

Sheet Posts (2)
A1: Post ID | B1: Platform | C1: Date | D1: Content Type | E1: Post Text | F1: Likes | G1: Shares | H1: Comments | I1: Impressions | J1: Reach | K1: Engagament | L1: Clicks | M1: Hashtags Used | N1: Campaign_Name
A2: P001 | B2: Twitter | C2: 45649 | D2: Reel | E2: Check out our latest reel on twitter! | F2: 1461 | G2: 184 | H2: 344 | I2: 21915 | J2: 21675 | K2: 1989 | L2: 15 | M2: #LiveForNow | N2: SummerSplash
A3: P001 | B3: Twitter | C3: 45649 | D3: Reel | E3: Check out our latest reel on twitter! | F3: 1461 | G3: 184 | H3: 344 | I3: 21915 | J3: 21675 | K3: 1989 | L3: 15 | M3: #AnytimeIsPepsiTime | N3: SummerSplash
A4: P002 | B4: Twitter | C4: 45750 | D4: Text | E4: Check out our latest text on twitter! | F4: 4054 | G4: 389 | H4: 493 | I4: 64864 | J4: 64383 | K4: 4936 | L4: 117 | M4: #PepsiCoRefresh | N4: FestiveRadiance
A5: P002 | B5: Twitter | C5: 45750 | D5: Text | E5: Check out our latest text on twitter! | F5: 4054 | G5: 389 | H5: 493 | I5: 64864 | J5: 64383 | K5: 4936 | L5: 117 | M5: #BetterWithPepsi | N5: FestiveRadiance
A6: P003 | B6: YouTube | C6: 45789 | D6: Reel | E6: Check out our latest reel on youtube! | F6: 2795 | G6: 105 | H6: 49 | I6: 53105 | J6: 52307 | K6: 2949 | L6: 204 | M6: #PepsiCoRefresh | N6: NewYearRefresh
A7: P004 | B7: Instagram | C7: 45516 | D7: Story | E7: Check out our latest story on instagram! | F7: 2404 | G7: 363 | H7: 138 | I7: 19232 | J7: 18636 | K7: 2905 | L7: 128 | M7: #ThirstyForMore | N7: DailyWellness
A8: P005 | B8: YouTube | C8: 45469 | D8: Reel | E8: Check out our latest reel on youtube! | F8: 3557 | G8: 687 | H8: 424 | I8: 71140 | J8: 70701 | K8: 4668 | L8: 224 | M8: #ThirstyForMore | N8: SummerSplash
A9: P005 | B9: YouTube | C9: 45469 | D9: Reel | E9: Check out our latest reel on youtube! | F9: 3557 | G9: 687 | H9: 424 | I9: 71140 | J9: 70701 | K9: 4668 | L9: 224 | M9: #PepsiCoRefresh | N9: SummerSplash
A10: P006 | B10: Facebook | C10: 45596 | D10: Carousel | E10: Check out our latest carousel on facebook! | F10: 2945 | G10: 930 | H10: 355 | I10: 23560 | J10: 23275 | K10: 4230 | L10: 256 | M10: #PepsiCoRefresh | N10: FestiveRadiance
A11: P007 | B11: Twitter | C11: 45467 | D11: Carousel | E11: Check out our latest carousel on twitter! | F11: 3860 | G11: 201 | H11: 279 | I11: 61760 | J11: 61660 | K11: 4340 | L11: 235 | M11: #PepsiCoRefresh | N11: FestiveRadiance
A12: P008 | B12: YouTube | C12: 45486 | D12: Image | E12: Check out our latest image on youtube! | F12: 3929 | G12: 262 | H12: 278 | I12: 43219 | J12: 42841 | K12: 4469 | L12: 39 | M12: #ThirstyForMore | N12: DailyWellness
A13: P009 | B13: Facebook | C13: 45534 | D13: Text | E13: Check out our latest text on facebook! | F13: 3784 | G13: 808 | H13: 404 | I13: 56760 | J13: 56343 | K13: 4996 | L13: 131 | M13: #PepsiCoRefresh | N13: FestiveRadiance
... A17: P013 | B17: YouTube | C17: 45614 | D17: Carousel | E17: Check out our latest carousel on youtube! | F17: 1171 | G17: 286 | H17: 231 | I17: 22249 | J17: 21282 | K17: 1688 | L17: 114 | M17: #ThirstyForMore | N17: SummerSplash
A18: P014 | B18: Facebook | C18: 45704 | D18: Story | E18: Check out our latest story on facebook! | F18: 4242 | G18: 555 | H18: 131 | I18: 33936 | J18: 33802 | K18: 4928 | L18: 265 | M18: #LiveForNow
A19: P015 | B19: Facebook | C19: 45589 | D19: Video | E19: Check out our latest video on facebook! | F19: 3888 | G19: 604 | H19: 128 | I19: 77760 | J19: 77167 | K19: 4620 | L19: 20 | M19: #LiveForNow | N19: SummerSplash
A20: P016 | B20: Facebook | C20: 45530 | D20: Text | E20: Check out our latest text on facebook! | F20: 3452 | G20: 377 | H20: 360 | I20: 55232 | J20: 55075 | K20: 4189 | L20: 87 | M20: #LiveForNow | N20: NewYearRefresh
A21: P017 | B21: Facebook | C21: 45782 | D21: Text | E21: Check out our latest text on facebook! | F21: 4441 | G21: 511 | H21: 70 | I21: 53292 | J21: 53082 | K21: 5022 | L21: 159 | M21: #ThirstyForMore | N21: DailyWellness
A22: P018 | B22: Instagram | C22: 45523 | D22: Reel | E22: Check out our latest reel on instagram! | F22: 3000 | G22: 382 | H22: 325 | I22: 36000 | J22: 35819 | K22: 3707 | L22: 19 | M22: #LiveForNow | N22: SummerSplash
A23: P019 | B23: Instagram | C23: 45466 | D23: Video | E23: Check out our latest video on instagram! | F23: 1071 | G23: 519 | H23: 22 | I23: 16065 | J23: 15865 | K23: 1612 | L23: 103 | M23: #PepsiCoRefresh | N23: DailyWellness
A24: P020 | B24: Instagram | C24: 45544 | D24: Carousel | E24: Check out our latest carousel on instagram! | F24: 4054 | G24: 488 | H24: 373 | I24: 77026 | J24: 76881 | K24: 4915 | L24: 25 | M24: #PepsiCoRefresh | N24: SummerSplash
A25: P021 | B25: Instagram | C25: 45661 | D25: Reel | E25: Check out our latest reel on instagram! | F25: 4838 | G25: 640 | H25: 128 | I25: 72570 | J25: 72396 | K25: 5606 | L25: 83 | M25: #LiveForNow | N25: DailyWellness
A26: P022 | B26: Facebook | C26: 45715 | D26: Text | E26: Check out our latest text on facebook! | F26: 1570 | G26: 187 | H26: 260 | I26: 25120 | J26: 24613 | K26: 2017 | L26: 133 | M26: #PepsiCoRefresh | N26: DailyWellness
A27: P023 | B27: Facebook | C27: 45602 | D27: Video | E27: Check out our latest video on facebook! | F27: 1606 | G27: 547 | H27: 316 | I27: 32120 | J27: 31736 | K27: 2469 | L27: 225 | M27: #PepsiCoRefresh | N27: FestiveRadiance
A28: P023 | B28: Facebook | C28: 45602 | D28: Video | E28: Check out our latest video on facebook! | F28: 1606 | G28: 547 | H28: 316 | I28: 32120 | J28: 31736 | K28: 2469 | L28: 225 | M28: #AnytimeIsPepsiTime | N28: FestiveRadiance
A29: P024 | B29: Facebook | C29: 45680 | D29: Video | E29: Check out our latest video on facebook! | F29: 3961 | G29: 761 | H29: 131 | I29: 67337 | J29: 66615 | K29: 4853 | L29: 161 | M29: #LiveForNow | N29: NewYearRefresh
A30: P025 | B30: Twitter | C30: 45757 | D30: Carousel | E30: Check out our latest carousel on twitter! | F30: 3128 | G30: 211 | H30: 197 | I30: 59432 | J30: 59182 | K30: 3536 | L30: 238 | M30: #ThirstyForMore
A31: P026 | B31: YouTube | C31: 45752 | D31: Reel | E31: Check out our latest reel on youtube! | F31: 3009 | G31: 413 | H31: 358 | I31: 42126 | J31: 41309 | K31: 3780 | L31: 211 | M31: #LiveForNow | N31: FestiveRadiance
A32: P027 | B32: YouTube | C32: 45552 | D32: Text | E32: Check out our latest text on youtube! | F32: 2076 | G32: 195 | H32: 104 | I32: 33216 | J32: 32244 | K32: 2375 | L32: 51 | M32: #LiveForNow | N32: DailyWellness
A33: P028 | B33: Instagram | C33: 45720 | D33: Video | E33: Check out our latest video on instagram! | F33: 432 | G33: 624 | H33: 123 | I33: 6912 | J33: 6259 | K33: 1179 | L33: 79 | M33: #LiveForNow | N33: DailyWellness
A34: P029 | B34: Instagram | C34: 45688 | D34: Carousel | E34: Check out our latest carousel on instagram! | F34: 2566 | G34: 118 | H34: 37 | I34: 12830 | J34: 12264 | K34: 2721 | L34: 221 | M34: #LiveForNow | N34: NewYearRefresh
A35: P030 | B35: Instagram | C35: 45713 | D35: Video | E35: Check out our latest video on instagram! | F35: 3095 | G35: 39 | H35: 78 | I35: 55710 | J35: 54808 | K35: 3212 | L35: 93 | M35: #ThirstyForMore
A36: P031 | B36: Instagram | C36: 45642 | D36: Text | E36: Check out our latest text on instagram! | F36: 438 | G36: 153 | H36: 275 | I36: 3066 | J36: 2701 | K36: 866 | L36: 282 | M36: #PepsiCoRefresh | N36: FestiveRadiance
A37: P032 | B37: Twitter | C37: 45504 | D37: Carousel | E37: Check out our latest carousel on twitter! | F37: 2278 | G37: 10 | H37: 321 | I37: 13668 | J37: 12676 | K37: 2609 | L37: 275 | M37: #ThirstyForMore | N37: SummerSplash
A38: P033 | B38: Facebook | C38: 45525 | D38: Image | E38: Check out our latest image on facebook! | F38: 1407 | G38: 400 | H38: 351 | I38: 16884 | J38: 15954 | K38: 2158 | L38: 113 | M38: #PepsiCoRefresh | N38: SummerSplash
A39: P034 | B39: Facebook | C39: 45742 | D39: Text | E39: Check out our latest text on facebook! | F39: 1652 | G39: 89 | H39: 357 | I39: 29736 | J39: 28771 | K39: 2098 | L39: 215 | M39: #PepsiCoRefresh | N39: NewYearRefresh
A40: P035 | B40: Instagram | C40: 45626 | D40: Video | E40: Check out our latest video on instagram! | F40: 3775 | G40: 16 | H40: 239 | I40: 33975 | J40: 33310 | K40: 4030 | L40: 271 | M40: #LiveForNow | N40: FestiveRadiance
A41: P036 | B41: Instagram | C41: 45766 | D41: Story | E41: Check out our latest story on instagram! | F41: 4518 | G41: 285 | H41: 383 | I41: 67770 | J41: 67621 | K41: 5186 | L41: 31 | M41: #ThirstyForMore | N41: FestiveRadiance
A42: P037 | B42: Facebook | C42: 45663 | D42: Carousel | E42: Check out our latest carousel on facebook! | F42: 3024 | G42: 925 | H42: 350 | I42: 24192 | J42: 23518 | K42: 4299 | L42: 36 | M42: #ThirstyForMore | N42: FestiveRadiance
A43: P038 | B43: YouTube | C43: 45705 | D43: Reel | E43: Check out our latest reel on youtube! | F43: 3138 | G43: 123 | H43: 291 | I43: 28242 | J43: 27550 | K43: 3552 | L43: 87 | M43: #PepsiCoRefresh | N43: DailyWellness
...

Sheet post
A1: Post ID | B1: Platform | C1: Date | D1: Content Type | E1: Post Text | F1: Likes | G1: Shares | H1: Comments | I1: Impressions | J1: Reach | K1: Clicks | L1: Engagement | M1: Campaign_Name | N1: Hashtags 1 | O1: Hashtags 2 | P1: Hashtags 3
A2: P001 | B2: Twitter | C2: 45649 | D2: Reel | E2: Check out our latest reel on twitter! | F2: 1461 | G2: 184 | H2: 344 | I2: 21915 | J2: 21675 | K2: 15 | L2: =[1]!Posts_Table[[#This Row],[Likes]]+[1]!Posts_Table[[#This Row],[Shares]]+[1]!Posts_Table[[#This Row],[Comments]] -> 1989 | M2: SummerSplash | N2: #LiveForNow | O2: #AnytimeIsPepsiTime
A3: P002 | B3: Twitter | C3: 45750 | D3: Text | E3: Check out our latest text on twitter! | F3: 4054 | G3: 389 | H3: 493 | I3: 64864 | J3: 64383 | K3: 117 | L3: =[1]!Posts_Table[[#This Row],[Likes]]+[1]!Posts_Table[[#This Row],[Shares]]+[1]!Posts_Table[[#This Row],[Comments]] -> 4936 | M3: FestiveRadiance | N3: #PepsiCoRefresh | O3: #BetterWithPepsi
A4: P003 | B4: YouTube | C4: 45789 | D4: Reel | E4: Check out our latest reel on youtube! | F4: 2795 | G4: 105 | H4: 49 | I4: 53105 | J4: 52307 | K4: 204 | L4: =[1]!Posts_Table[[#This Row],[Likes]]+[1]!Posts_Table[[#This Row],[Shares]]+[1]!Posts_Table[[#This Row],[Comments]] -> 2949 | M4: NewYearRefresh | N4: #PepsiCoRefresh
A5: P004 | B5: Instagram | C5: 45516 | D5: Story | E5: Check out our latest story on instagram! | F5: 2404 | G5: 363 | H5: 138 | I5: 19232 | J5: 18636 | K5: 128 | L5: =[1]!Posts_Table[[#This Row],[Likes]]+[1]!Posts_Table[[#This Row],[Shares]]+[1]!Posts_Table[[#This Row],[Comments]] -> 2905 | M5: DailyWellness | N5: #ThirstyForMore
A6: P005 | B6: YouTube | C6: 45469 | D6: Reel | E6: Check out our latest reel on youtube! | F6: 3557 | G6: 687 | H6: 424 | I6: 71140 | J6: 70701 | K6: 224 | L6: =[1]!Posts_Table[[#This Row],[Likes]]+[1]!Posts_Table[[#This Row],[Shares]]+[1]!Posts_Table[[#This Row],[Comments]] -> 4668 | M6: SummerSplash | N6: #ThirstyForMore | O6: #PepsiCoRefresh
A7: P006 | B7: Facebook | C7: 45596 | D7: Carousel | E7: Check out our latest carousel on facebook! | F7: 2945 | G7: 930 | H7: 355 | I7: 23560 | J7: 23275 | K7: 256 | L7: =[1]!Posts_Table[[#This Row],[Likes]]+[1]!Posts_Table[[#This Row],[Shares]]+[1]!Posts_Table[[#This Row],[Comments]] -> 4230 | M7: FestiveRadiance | N7: #PepsiCoRefresh
A8: P007 | B8: Twitter | C8: 45467 | D8: Carousel | E8: Check out our latest carousel on twitter! | F8: 3860 | G8: 201 | H8: 279 | I8: 61760 | J8: 61660 | K8: 235 | L8: =[1]!Posts_Table[[#This Row],[Likes]]+[1]!Posts_Table[[#This Row],[Shares]]+[1]!Posts_Table[[#This Row],[Comments]] -> 4340 | M8: FestiveRadiance | N8: #PepsiCoRefresh
A9: P008 | B9: YouTube | C9: 45486 | D9: Image | E9: Check out our latest image on youtube! | F9: 3929 | G9: 262 | H9: 278 | I9: 43219 | J9: 42841 | K9: 39 | L9: =[1]!Posts_Table[[#This Row],[Likes]]+[1]!Posts_Table[[#This Row],[Shares]]+[1]!Posts_Table[[#This Row],[Comments]] -> 4469 | M9: DailyWellness | N9: #ThirstyForMore
A10: P009 | B10: Facebook | C10: 45534 | D10: Text | E10: Check out our latest text on facebook! | F10: 3784 | G10: 808 | H10: 404 | I10: 56760 | J10: 56343 | K10: 131 | L10: =[1]!Posts_Table[[#This Row],[Likes]]+[1]!Posts_Table[[#This Row],[Shares]]+[1]!Posts_Table[[#This Row],[Comments]] -> 4996 | M10: FestiveRadiance | N10: #PepsiCoRefresh
A11: P010 | B11: Facebook | C11: 45727 | D11: Image | E11: Check out our latest image on facebook! | F11: 4241 | G11: 902 | H11: 47 | I11: 72097 | J11: 71598 | K11: 167 | L11: =[1]!Posts_Table[[#This Row],[Likes]]+[1]!Posts_Table[[#This Row],[Shares]]+[1]!Posts_Table[[#This Row],[Comments]] -> 5190 | M11: FestiveRadiance | N11: #PepsiCoRefresh
A12: P011 | B12: Instagram | C12: 45690 | D12: Story | E12: Check out our latest story on instagram! | F12: 1792 | G12: 614 | H12: 497 | I12: 25088 | J12: 24675 | K12: 65 | L12: =[1]!Posts_Table[[#This Row],[Likes]]+[1]!Posts_Table[[#This Row],[Shares]]+[1]!Posts_Table[[#This Row],[Comments]] -> 2903 | M12: DailyWellness | N12: #LiveForNow
A13: P012 | B13: Facebook | C13: 45494 | D13: Reel | E13: Check out our latest reel on facebook! | F13: 1946 | G13: 686 | H13: 377 | I13: 23352 | J13: 22982 | K13: 213 | L13: =[1]!Posts_Table[[#This Row],[Likes]]+[1]!Posts_Table[[#This Row],[Shares]]+[1]!Posts_Table[[#This Row],[Comments]] -> 3009 | M13: NewYearRefresh | N13: #LiveForNow
A14: P013 | B14: YouTube | C14: 45614 | D14: Carousel | E14: Check out our latest carousel on youtube! | F14: 1171 | G14: 286 | H14: 231 | I14: 22249 | J14: 21282 | K14: 114 | L14: =[1]!Posts_Table[[#This Row],[Likes]]+[1]!Posts_Table[[#This Row],[Shares]]+[1]!Posts_Table[[#This Row],[Comments]] -> 1688 | M14: SummerSplash | N14: #ThirstyForMore
A15: P014 | B15: Facebook | C15: 45704 | D15: Story | E15: Check out our latest story on facebook! | F15: 4242 | G15: 555 | H15: 131 | I15: 33936 | J15: 33802 | K15: 265 | L15: =[1]!Posts_Table[[#This Row],[Likes]]+[1]!Posts_Table[[#This Row],[Shares]]+[1]!Posts_Table[[#This Row],[Comments]] -> 4928 | N15: #LiveForNow
A16: P015 | B16: Facebook | C16: 45589 | D16: Video | E16: Check out our latest video on facebook! | F16: 3888 | G16: 604 | H16: 128 | I16: 77760 | J16: 77167 | K16: 20 | L16: =[1]!Posts_Table[[#This Row],[Likes]]+[1]!Posts_Table[[#This Row],[Shares]]+[1]!Posts_Table[[#This Row],[Comments]] -> 4620 | M16: SummerSplash | N16: #LiveForNow
A17: P016 | B17: Facebook | C17: 45530 | D17: Text | E17: Check out our latest text on facebook! | F17: 3452 | G17: 377 | H17: 360 | I17: 55232 | J17: 55075 | K17: 87 | L17: =[1]!Posts_Table[[#This Row],[Likes]]+[1]!Posts_Table[[#This Row],[Shares]]+[1]!Posts_Table[[#This Row],[Comments]] -> 4189 | M17: NewYearRefresh | N17: #LiveForNow
A18: P017 | B18: Facebook | C18: 45782 | D18: Text | E18: Check out our latest text on facebook! | F18: 4441 | G18: 511 | H18: 70 | I18: 53292 | J18: 53082 | K18: 159 | L18: =[1]!Posts_Table[[#This Row],[Likes]]+[1]!Posts_Table[[#This Row],[Shares]]+[1]!Posts_Table[[#This Row],[Comments]] -> 5022 | M18: DailyWellness | N18: #ThirstyForMore
A19: P018 | B19: Instagram | C19: 45523 | D19: Reel | E19: Check out our latest reel on instagram! | F19: 3000 | G19: 382 | H19: 325 | I19: 36000 | J19: 35819 | K19: 19 | L19: =[1]!Posts_Table[[#This Row],[Likes]]+[1]!Posts_Table[[#This Row],[Shares]]+[1]!Posts_Table[[#This Row],[Comments]] -> 3707 | M19: SummerSplash | N19: #LiveForNow
A20: P019 | B20: Instagram | C20: 45466 | D20: Video | E20: Check out our latest video on instagram! | F20: 1071 | G20: 519 | H20: 22 | I20: 16065 | J20: 15865 | K20: 103 | L20: =[1]!Posts_Table[[#This Row],[Likes]]+[1]!Posts_Table[[#This Row],[Shares]]+[1]!Posts_Table[[#This Row],[Comments]] -> 1612 | M20: DailyWellness | N20: #PepsiCoRefresh
A21: P020 | B21: Instagram | C21: 45544 | D21: Carousel | E21: Check out our latest carousel on instagram! | F21: 4054 | G21: 488 | H21: 373 | I21: 77026 | J21: 76881 | K21: 25 | L21: =[1]!Posts_Table[[#This Row],[Likes]]+[1]!Posts_Table[[#This Row],[Shares]]+[1]!Posts_Table[[#This Row],[Comments]] -> 4915 | M21: SummerSplash | N21: #PepsiCoRefresh
A22: P021 | B22: Instagram | C22: 45661 | D22: Reel | E22: Check out our latest reel on instagram! | F22: 4838 | G22: 640 | H22: 128 | I22: 72570 | J22: 72396 | K22: 83 | L22: =[1]!Posts_Table[[#This Row],[Likes]]+[1]!Posts_Table[[#This Row],[Shares]]+[1]!Posts_Table[[#This Row],[Comments]] -> 5606 | M22: DailyWellness | N22: #LiveForNow
A23: P022 | B23: Facebook | C23: 45715 | D23: Text | E23: Check out our latest text on facebook! | F23: 1570 | G23: 187 | H23: 260 | I23: 25120 | J23: 24613 | K23: 133 | L23: =[1]!Posts_Table[[#This Row],[Likes]]+[1]!Posts_Table[[#This Row],[Shares]]+[1]!Posts_Table[[#This Row],[Comments]] -> 2017 | M23: DailyWellness | N23: #PepsiCoRefresh
A24: P023 | B24: Facebook | C24: 45602 | D24: Video | E24: Check out our latest video on facebook! | F24: 1606 | G24: 547 | H24: 316 | I24: 32120 | J24: 31736 | K24: 225 | L24: =[1]!Posts_Table[[#This Row],[Likes]]+[1]!Posts_Table[[#This Row],[Shares]]+[1]!Posts_Table[[#This Row],[Comments]] -> 2469 | M24: FestiveRadiance | N24: #PepsiCoRefresh | O24: #AnytimeIsPepsiTime
A25: P024 | B25: Facebook | C25: 45680 | D25: Video | E25: Check out our latest video on facebook! | F25: 3961 | G25: 761 | H25: 131 | I25: 67337 | J25: 66615 | K25: 161 | L25: =[1]!Posts_Table[[#This Row],[Likes]]+[1]!Posts_Table[[#This Row],[Shares]]+[1]!Posts_Table[[#This Row],[Comments]] -> 4853 | M25: NewYearRefresh | N25: #LiveForNow
A26: P025 | B26: Twitter | C26: 45757 | D26: Carousel | E26: Check out our latest carousel on twitter! | F26: 3128 | G26: 211 | H26: 197 | I26: 59432 | J26: 59182 | K26: 238 | L26: =[1]!Posts_Table[[#This Row],[Likes]]+[1]!Posts_Table[[#This Row],[Shares]]+[1]!Posts_Table[[#This Row],[Comments]] -> 3536 | N26: #ThirstyForMore
A27: P026 | B27: YouTube | C27: 45752 | D27: Reel | E27: Check out our latest reel on youtube! | F27: 3009 | G27: 413 | H27: 358 | I27: 42126 | J27: 41309 | K27: 211 | L27: =[1]!Posts_Table[[#This Row],[Likes]]+[1]!Posts_Table[[#This Row],[Shares]]+[1]!Posts_Table[[#This Row],[Comments]] -> 3780 | M27: FestiveRadiance | N27: #LiveForNow
A28: P027 | B28: YouTube | C28: 45552 | D28: Text | E28: Check out our latest text on youtube! | F28: 2076 | G28: 195 | H28: 104 | I28: 33216 | J28: 32244 | K28: 51 | L28: =[1]!Posts_Table[[#This Row],[Likes]]+[1]!Posts_Table[[#This Row],[Shares]]+[1]!Posts_Table[[#This Row],[Comments]] -> 2375 | M28: DailyWellness | N28: #LiveForNow
A29: P028 | B29: Instagram | C29: 45720 | D29: Video | E29: Check out our latest video on instagram! | F29: 432 | G29: 624 | H29: 123 | I29: 6912 | J29: 6259 | K29: 79 | L29: =[1]!Posts_Table[[#This Row],[Likes]]+[1]!Posts_Table[[#This Row],[Shares]]+[1]!Posts_Table[[#This Row],[Comments]] -> 1179 | M29: DailyWellness | N29: #LiveForNow
A30: P029 | B30: Instagram | C30: 45688 | D30: Carousel | E30: Check out our latest carousel on instagram! | F30: 2566 | G30: 118 | H30: 37 | I30: 12830 | J30: 12264 | K30: 221 | L30: =[1]!Posts_Table[[#This Row],[Likes]]+[1]!Posts_Table[[#This Row],[Shares]]+[1]!Posts_Table[[#This Row],[Comments]] -> 2721 | M30: NewYearRefresh | N30: #LiveForNow
A31: P030 | B31: Instagram | C31: 45713 | D31: Video | E31: Check out our latest video on instagram! | F31: 3095 | G31: 39 | H31: 78 | I31: 55710 | J31: 54808 | K31: 93 | L31: =[1]!Posts_Table[[#This Row],[Likes]]+[1]!Posts_Table[[#This Row],[Shares]]+[1]!Posts_Table[[#This Row],[Comments]] -> 3212 | N31: #ThirstyForMore
A32: P031 | B32: Instagram | C32: 45642 | D32: Text | E32: Check out our latest text on instagram! | F32: 438 | G32: 153 | H32: 275 | I32: 3066 | J32: 2701 | K32: 282 | L32: =[1]!Posts_Table[[#This Row],[Likes]]+[1]!Posts_Table[[#This Row],[Shares]]+[1]!Posts_Table[[#This Row],[Comments]] -> 866 | M32: FestiveRadiance | N32: #PepsiCoRefresh
A33: P032 | B33: Twitter | C33: 45504 | D33: Carousel | E33: Check out our latest carousel on twitter! | F33: 2278 | G33: 10 | H33: 321 | I33: 13668 | J33: 12676 | K33: 275 | L33: =[1]!Posts_Table[[#This Row],[Likes]]+[1]!Posts_Table[[#This Row],[Shares]]+[1]!Posts_Table[[#This Row],[Comments]] -> 2609 | M33: SummerSplash | N33: #ThirstyForMore
A34: P033 | B34: Facebook | C34: 45525 | D34: Image | E34: Check out our latest image on facebook! | F34: 1407 | G34: 400 | H34: 351 | I34: 16884 | J34: 15954 | K34: 113 | L34: =[1]!Posts_Table[[#This Row],[Likes]]+[1]!Posts_Table[[#This Row],[Shares]]+[1]!Posts_Table[[#This Row],[Comments]] -> 2158 | M34: SummerSplash | N34: #PepsiCoRefresh
A35: P034 | B35: Facebook | C35: 45742 | D35: Text | E35: Check out our latest text on facebook! | F35: 1652 | G35: 89 | H35: 357 | I35: 29736 | J35: 28771 | K35: 215 | L35: =[1]!Posts_Table[[#This Row],[Likes]]+[1]!Posts_Table[[#This Row],[Shares]]+[1]!Posts_Table[[#This Row],[Comments]] -> 2098 | M35: NewYearRefresh | N35: #PepsiCoRefresh
A36: P035 | B36: Instagram | C36: 45626 | D36: Video | E36: Check out our latest video on instagram! | F36: 3775 | G36: 16 | H36: 239 | I36: 33975 | J36: 33310 | K36: 271 | L36: =[1]!Posts_Table[[#This Row],[Likes]]+[1]!Posts_Table[[#This Row],[Shares]]+[1]!Posts_Table[[#This Row],[Comments]] -> 4030 | M36: FestiveRadiance | N36: #LiveForNow
A37: P036 | B37: Instagram | C37: 45766 | D37: Story | E37: Check out our latest story on instagram! | F37: 4518 | G37: 285 | H37: 383 | I37: 67770 | J37: 67621 | K37: 31 | L37: =[1]!Posts_Table[[#This Row],[Likes]]+[1]!Posts_Table[[#This Row],[Shares]]+[1]!Posts_Table[[#This Row],[Comments]] -> 5186 | M37: FestiveRadiance | N37: #ThirstyForMore
A38: P037 | B38: Facebook | C38: 45663 | D38: Carousel | E38: Check out our latest carousel on facebook! | F38: 3024 | G38: 925 | H38: 350 | I38: 24192 | J38: 23518 | K38: 36 | L38: =[1]!Posts_Table[[#This Row],[Likes]]+[1]!Posts_Table[[#This Row],[Shares]]+[1]!Posts_Table[[#This Row],[Comments]] -> 4299 | M38: FestiveRadiance | N38: #ThirstyForMore
A39: P038 | B39: YouTube | C39: 45705 | D39: Reel | E39: Check out our latest reel on youtube! | F39: 3138 | G39: 123 | H39: 291 | I39: 28242 | J39: 27550 | K39: 87 | L39: =[1]!Posts_Table[[#This Row],[Likes]]+[1]!Posts_Table[[#This Row],[Shares]]+[1]!Posts_Table[[#This Row],[Comments]] -> 3552 | M39: DailyWellness | N39: #PepsiCoRefresh
A40: P039 | B40: Facebook | C40: 45621 | D40: Image | E40: Check out our latest image on facebook! | F40: 3564 | G40: 629 | H40: 177 | I40: 60588 | J40: 59627 | K40: 92 | L40: =[1]!Posts_Table[[#This Row],[Likes]]+[1]!Posts_Table[[#This Row],[Shares]]+[1]!Posts_Table[[#This Row],[Comments]] -> 4370 | N40: #PepsiCoRefresh
...

Sheet Engagement Summary
A1: Week_Start_Date | B1: Platform | C1: New_Followers | D1: Unfollows | E1: Total_Followers | F1: Engagement_Rate | G1: Ad_Spend | H1: Net followers
A2: 2024-06-03 | B2: Instagram | C2: 1135 | D2: 88 | E2: 344084 | F2: 8.06 | G2: 5904 | H2: =(C2-D2) -> 1047
A3: 2024-06-03 | B3: Facebook | C3: 1312 | D3: 310 | E3: 42654 | F3: 4.98 | G3: 9566 | H3: =(C3-D3) -> 1002
A4: 2024-06-03 | B4: Twitter | C4: 584 | D4: 169 | E4: 146834 | F4: 8.31 | G4: 26752 | H4: =(C4-D4) -> 415
A5: 2024-06-03 | B5: YouTube | C5: 1535 | D5: 445 | E5: 395536 | F5: 4.11 | G5: 30671 | H5: =(C5-D5) -> 1090
A6: 2024-06-10 | B6: Instagram | C6: 656 | D6: 139 | E6: 49157 | F6: 9.05 | G6: 9920 | H6: =(C6-D6) -> 517
A7: 2024-06-10 | B7: Facebook | C7: 1697 | D7: 414 | E7: 316555 | F7: 2.37 | G7: 7924 | H7: =(C7-D7) -> 1283
A8: 2024-06-10 | B8: Twitter | C8: 436 | D8: 250 | E8: 254347 | F8: 4.01 | G8: 8912 | H8: =(C8-D8) -> 186
A9: 2024-06-10 | B9: YouTube | C9: 1197 | D9: 203 | E9: 413878 | F9: 3.16 | G9: 21205 | H9: =(C9-D9) -> 994
A10: 2024-06-17 | B10: Instagram | C10: 1048 | D10: 155 | E10: 456946 | F10: 2.46 | G10: 11329 | H10: =(C10-D10) -> 893
A11: 2024-06-17 | B11: Facebook | C11: 1753 | D11: 371 | E11: 169496 | F11: 8.11 | G11: 46670 | H11: =(C11-D11) -> 1382
A12: 2024-06-17 | B12: Twitter | C12: 1335 | D12: 40 | E12: 122732 | F12: 8.19 | G12: 22482 | H12: =(C12-D12) -> 1295
A13: 2024-06-17 | B13: YouTube | C13: 403 | D13: 66 | E13: 382851 | F13: 3.49 | G13: 24313 | H13: =(C13-D13) -> 337
... A201: 2025-05-12 | B201: YouTube | C201: 119 | D201: 456 | E201: 82558 | F201: 6.81 | G201: 12174 | H201: =(C201-D201) -> -337

Sheet Campaign MetaData
A1: Campaign_Name | B1: Start_Date | C1: End_Date | D1: Objective | E1: Total_Budget | F1: Target_Platforms | G1: Primary_Hashtags | H1: Primary_Hashtags 2
A2: NewYearRefresh | B2: 2024-12-25 | C2: 2025-01-10 | D2: Product Launch | E2: 250000 | F2: Facebook,Twitter | G2: #SmoothLikeNitroPepsi
A3: FestiveRadiance | B3: 2024-10-01 | C3: 2024-10-31 | D3: Engagement | E3: 200000 | F3: Instagram,YouTube | G3: #AnytimeIsPepsiTime
A4: DailyWellness | B4: 2025-03-01 | C4: 2025-03-31 | D4: Traffic | E4: 180000 | F4: Instagram,Twitter | G4: #BetterWithPepsi | H4: #LiveForNow
A5: SummerSplash | B5: 2024-06-15 | C5: 2024-07-15 | D5: Brand Awareness | E5: 150000 | F5: Instagram,Facebook | G5: #ThirstyForMore | H5: #PepsiCoRefresh

Sheet Campaign Result
A1: Campaign_Name | B1: Start_Date | C1: End_Date | D1: Campaign_Period | E1: Pre_Campaign | F1: Engagement During | G1: Engagement Before | H1: Daily Engagement During | I1: Daily Engagement Before | J1: Engagement Uplift %
A2: DailyWellness | B2: 2025-03-01 | C2: 2025-03-31 | D2: =C2-B2+1 -> 31 | E2: =B2-D2 -> 45686 | F2: =SUMIFS(post!$L:$L, post!$C:$C, ">=" & B2, post!$C:$C, "<=" & C2) -> 106020 | G2: =SUMIFS(post!$L:$L, post!$C:$C, ">=" & (B2-30), post!$C:$C, "<=" & B2) -> 72976 | H2: =F2/D2 -> 3420 | I2: =G2/D2 -> 2354.0645 | J2: =(H2-I2)/H2*100 -> 31.167704
A3: NewYearRefresh | B3: 2024-12-25 | C3: 2025-01-10 | D3: =C3-B3+1 -> 17 | E3: =B3-D3 -> 45634 | F3: =SUMIFS(post!$L:$L, post!$C:$C, ">=" & B3, post!$C:$C, "<=" & C3) -> 33044 | G3: =SUMIFS(post!$L:$L, post!$C:$C, ">=" & (B3-30), post!$C:$C, "<=" & B3) -> 104809 | H3: =F3/D3 -> 1943.7647 | I3: =G3/D3 -> 6165.2353 | J3: =(H3-I3)/H3*100 -> -217.18012
A4: FestiveRadiance | B4: 2024-10-01 | C4: 2024-10-31 | D4: =C4-B4+1 -> 31 | E4: =B4-D4 -> 45535 | F4: =SUMIFS(post!$L:$L, post!$C:$C, ">=" & B4, post!$C:$C, "<=" & C4) -> 137691 | G4: =SUMIFS(post!$L:$L, post!$C:$C, ">=" & (B4-30), post!$C:$C, "<=" & B4) -> 50228 | H4: =F4/D4 -> 4441.6452 | I4: =G4/D4 -> 1620.2581 | J4: =(H4-I4)/H4*100 -> 63.521218
A5: SummerSplash | B5: 2024-06-15 | C5: 2024-07-15 | D5: =C5-B5+1 -> 31 | E5: =B5-D5 -> 45427 | F5: =SUMIFS(post!$L:$L, post!$C:$C, ">=" & B5, post!$C:$C, "<=" & C5) -> 103773 | G5: =SUMIFS(post!$L:$L, post!$C:$C, ">=" & (B5-30), post!$C:$C, "<=" & B5) -> 47286 | H5: =F5/D5 -> 3347.5161 | I5: =G5/D5 -> 1525.3548 | J5: =(H5-I5)/H5*100 -> 54.433234
D15: Campaign_Name | E15: Total_Budget | F15: Total_Engagement | G15: ROI | H15: Rank
D16: NewYearRefresh | E16: 250000 | F16: =SUMIFS(post!$L$2:$L$301,post!$M$2:$M$301,"=" & D16 ) -> 232821 | G16: =E16/F16 -> 1.0737863 | H16: =_xlfn.RANK.EQ(G16,$G$16:$G$19,0) -> 1
D17: FestiveRadiance | E17: 200000 | F17: =SUMIFS(post!$L$2:$L$301,post!$M$2:$M$301,"=" & D17 ) -> 201739 | G17: =E17/F17 -> 0.99137995 | H17: =_xlfn.RANK.EQ(G17,$G$16:$G$19,0) -> 2
D18: SummerSplash | E18: 150000 | F18: =SUMIFS(post!$L$2:$L$301,post!$M$2:$M$301,"=" & D18 ) -> 173901 | G18: =E18/F18 -> 0.86255973 | H18: =_xlfn.RANK.EQ(G18,$G$16:$G$19,0) -> 3
D19: DailyWellness | E19: 180000 | F19: =SUMIFS(post!$L$2:$L$301,post!$M$2:$M$301,"=" & D19 ) -> 240483 | G19: =E19/F19 -> 0.74849366 | H19: =_xlfn.RANK.EQ(G19,$G$16:$G$19,0) -> 4
